Workbook
Name BtfeIndexSheetTable: #REF!
Name IQ_CH: 110000
Name IQ_CQ: 5000
Name IQ_CY: 10000
Name IQ_DAILY: 500000
Name IQ_FH: 100000
Name IQ_FQ: 500
Name IQ_FY: 1000
Name IQ_LTM: 2000
Name IQ_MONTH: 15000
Name IQ_NTM: 6000
Name IQ_WEEK: 50000
Name IQ_YTD: 3000

Sheet Sheet1
A1: PDF | B1: Company | C1: Theme | D1: Definition | E1: Extracted Commentary | F1: Match/No-match | G1: Similarity Score | H1: Commentary
A2: C:\Users\73335\OneDrive - Bain\Desktop\FS-ECR-repo\fs-earnings_call_reader\src\notebooks\submission_to_fs_6thAug\FS PDFs\American International Group Inc._Earnings Call_2023-05-05_English.pdf | B2: American International Group Inc. | C2: Macro factors | D2: Tag a commentary under the Macro Factors theme if it includes any reference—explicit or implicit—to the broader macroeconomic environment or external systemic influences affecting business performance. This includes mentions of economic slowdown, recession, uncertainty, market cycles, credit losses, or challenging operating conditions. Tag if the discussion involves monetary indicators such as inflation, interest rates (domestic or foreign), discount rates, investment yields, credit spreads, or currency and foreign exchange impacts. Also include insurance and financial-specific macro drivers such as mortality experience (including seasonal or pandemic-related surges), expected credit losses (ECL), movements in insurance liabilities, or gains/losses tied to market conditions. Furthermore, tag content that refers to external shocks like pandemics (e.g. COVID-19), natural disasters (e.g. hurricanes, floods), or geopolitical disruptions. Additionally, include discussions that indirectly reflect macro context—such as tough environments, changes in investor sentiment, demand volatility, or strategic repositioning in response to macro trends—even if specific macro terms are not used. | E2: 1. We continue to make meaningful progress across AIG and achieve important milestones, even in the face of ongoing complexity in the insurance industry, volatile market conditions and general economic uncertainty. | F2: {=_xldudf_BOARDFLARE_FMATCH(E2,'FS Consolidated Comments'!C$76:C$137,0.13)} -> #VALUE! | G2: {=_FV(F2,"Similarity")} -> 0 | H2: {=_FV(F2,"Match")}
A3: C:\Users\73335\OneDrive - Bain\Desktop\FS-ECR-repo\fs-earnings_call_reader\src\notebooks\submission_to_fs_6thAug\FS PDFs\American International Group Inc._Earnings Call_2023-05-05_English.pdf | B3: American International Group Inc. | C3: Macro factors | D3: Tag a commentary under the Macro Factors theme if it includes any reference—explicit or implicit—to the broader macroeconomic environment or external systemic influences affecting business performance. This includes mentions of economic slowdown, recession, uncertainty, market cycles, credit losses, or challenging operating conditions. Tag if the discussion involves monetary indicators such as inflation, interest rates (domestic or foreign), discount rates, investment yields, credit spreads, or currency and foreign exchange impacts. Also include insurance and financial-specific macro drivers such as mortality experience (including seasonal or pandemic-related surges), expected credit losses (ECL), movements in insurance liabilities, or gains/losses tied to market conditions. Furthermore, tag content that refers to external shocks like pandemics (e.g. COVID-19), natural disasters (e.g. hurricanes, floods), or geopolitical disruptions. Additionally, include discussions that indirectly reflect macro context—such as tough environments, changes in investor sentiment, demand volatility, or strategic repositioning in response to macro trends—even if specific macro terms are not used. | E3: 2. During the first quarter, we were prepared to launch a secondary offering of Corebridge common stock, but chose not to proceed when equity markets became volatile due to issues in the financial sector. | F3: {=_xldudf_BOARDFLARE_FMATCH(E3,'FS Consolidated Comments'!C$76:C$137,0.13)} -> #VALUE! | G3: {=_FV(F3,"Similarity")} -> 0 | H3: {=_FV(F3,"Match")}
A4: C:\Users\73335\OneDrive - Bain\Desktop\FS-ECR-repo\fs-earnings_call_reader\src\notebooks\submission_to_fs_6thAug\FS PDFs\American International Group Inc._Earnings Call_2023-05-05_English.pdf | B4: American International Group Inc. | C4: Macro factors | D4: Tag a commentary under the Macro Factors theme if it includes any reference—explicit or implicit—to the broader macroeconomic environment or external systemic influences affecting business performance. This includes mentions of economic slowdown, recession, uncertainty, market cycles, credit losses, or challenging operating conditions. Tag if the discussion involves monetary indicators such as inflation, interest rates (domestic or foreign), discount rates, investment yields, credit spreads, or currency and foreign exchange impacts. Also include insurance and financial-specific macro drivers such as mortality experience (including seasonal or pandemic-related surges), expected credit losses (ECL), movements in insurance liabilities, or gains/losses tied to market conditions. Furthermore, tag content that refers to external shocks like pandemics (e.g. COVID-19), natural disasters (e.g. hurricanes, floods), or geopolitical disruptions. Additionally, include discussions that indirectly reflect macro context—such as tough environments, changes in investor sentiment, demand volatility, or strategic repositioning in response to macro trends—even if specific macro terms are not used. | E4: 3. Shifting back to our $15 \%$ net premiums written growth in the first quarter, this result was impressive despite the headwinds we continue to see in Financial Lines, where overall net premiums written contracted 9\% due to increased competition putting pressure on pricing as well as continued slowdown in M\&A and other transactional business. | F4: {=_xldudf_BOARDFLARE_FMATCH(E4,'FS Consolidated Comments'!C$76:C$137,0.13)} -> #VALUE! | G4: {=_FV(F4,"Similarity")} -> 0.21 | H4: {=_FV(F4,"Match")} -> where overall net premiums written contracted 9% due to increased competition putting pressure on pricing as well as continued slowdown in M&A and other transactional business.
A5: C:\Users\73335\OneDrive - Bain\Desktop\FS-ECR-repo\fs-earnings_call_reader\src\notebooks\submission_to_fs_6thAug\FS PDFs\American International Group Inc._Earnings Call_2023-05-05_English.pdf | B5: American International Group Inc. | C5: Macro factors | D5: Tag a commentary under the Macro Factors theme if it includes any reference—explicit or implicit—to the broader macroeconomic environment or external systemic influences affecting business performance. This includes mentions of economic slowdown, recession, uncertainty, market cycles, credit losses, or challenging operating conditions. Tag if the discussion involves monetary indicators such as inflation, interest rates (domestic or foreign), discount rates, investment yields, credit spreads, or currency and foreign exchange impacts. Also include insurance and financial-specific macro drivers such as mortality experience (including seasonal or pandemic-related surges), expected credit losses (ECL), movements in insurance liabilities, or gains/losses tied to market conditions. Furthermore, tag content that refers to external shocks like pandemics (e.g. COVID-19), natural disasters (e.g. hurricanes, floods), or geopolitical disruptions. Additionally, include discussions that indirectly reflect macro context—such as tough environments, changes in investor sentiment, demand volatility, or strategic repositioning in response to macro trends—even if specific macro terms are not used. | E5: 4. Turning to capital management. The first quarter marked another quarter of continued progress and execution of our balanced strategy. In addition to the first quarter share repurchases and dividends that I mentioned earlier, against the backdrop of an unstable macroeconomic environment, we thought it was prudent to raise $\$ 750$ million of debt at the end of March. | F5: {=_xldudf_BOARDFLARE_FMATCH(E5,'FS Consolidated Comments'!C$76:C$137,0.13)} -> #VALUE! | G5: {=_FV(F5,"Similarity")} -> 0.22 | H5: {=_FV(F5,"Match")} -> In addition to the first quarter share repurchases and dividends that I mentioned earlier, against the backdrop of an unstable macroeconomic environment, we thought it was prudent to raise $750 million of debt at the end of March.
A6: C:\Users\73335\OneDrive - Bain\Desktop\FS-ECR-repo\fs-earnings_call_reader\src\notebooks\submission_to_fs_6thAug\FS PDFs\American International Group Inc._Earnings Call_2023-05-05_English.pdf | B6: American International Group Inc. | C6: Macro factors | D6: Tag a commentary under the Macro Factors theme if it includes any reference—explicit or implicit—to the broader macroeconomic environment or external systemic influences affecting business performance. This includes mentions of economic slowdown, recession, uncertainty, market cycles, credit losses, or challenging operating conditions. Tag if the discussion involves monetary indicators such as inflation, interest rates (domestic or foreign), discount rates, investment yields, credit spreads, or currency and foreign exchange impacts. Also include insurance and financial-specific macro drivers such as mortality experience (including seasonal or pandemic-related surges), expected credit losses (ECL), movements in insurance liabilities, or gains/losses tied to market conditions. Furthermore, tag content that refers to external shocks like pandemics (e.g. COVID-19), natural disasters (e.g. hurricanes, floods), or geopolitical disruptions. Additionally, include discussions that indirectly reflect macro context—such as tough environments, changes in investor sentiment, demand volatility, or strategic repositioning in response to macro trends—even if specific macro terms are not used. | E6: 5. As Peter noted, L\&R premiums and deposits were very strong at $\$ 10.4$ billion. Notably, Individual Retirement sales were $\$ 4.9$ billion, a $26 \%$ increase over the prior year quarter with record levels of fixed and fixed index annuity sales because of higher crediting rates. | F6: {=_xldudf_BOARDFLARE_FMATCH(E6,'FS Consolidated Comments'!C$76:C$137,0.13)} -> #VALUE! | G6: {=_FV(F6,"Similarity")} -> 0 | H6: {=_FV(F6,"Match")}
A7: C:\Users\73335\OneDrive - Bain\Desktop\FS-ECR-repo\fs-earnings_call_reader\src\notebooks\submission_to_fs_6thAug\FS PDFs\American International Group Inc._Earnings Call_2023-05-05_English.pdf | B7: American International Group Inc. | C7: Macro factors | D7: Tag a commentary under the Macro Factors theme if it includes any reference—explicit or implicit—to the broader macroeconomic environment or external systemic influences affecting business performance. This includes mentions of economic slowdown, recession, uncertainty, market cycles, credit losses, or challenging operating conditions. Tag if the discussion involves monetary indicators such as inflation, interest rates (domestic or foreign), discount rates, investment yields, credit spreads, or currency and foreign exchange impacts. Also include insurance and financial-specific macro drivers such as mortality experience (including seasonal or pandemic-related surges), expected credit losses (ECL), movements in insurance liabilities, or gains/losses tied to market conditions. Furthermore, tag content that refers to external shocks like pandemics (e.g. COVID-19), natural disasters (e.g. hurricanes, floods), or geopolitical disruptions. Additionally, include discussions that indirectly reflect macro context—such as tough environments, changes in investor sentiment, demand volatility, or strategic repositioning in response to macro trends—even if specific macro terms are not used. | E7: 6. Income on fixed maturities and loans rose by $\$ 573$ million over the prior year, with average new money reinvestment rates of $5.35 \%$, about 220 basis points above sales and maturities. | F7: {=_xldudf_BOARDFLARE_FMATCH(E7,'FS Consolidated Comments'!C$76:C$137,0.13)} -> #VALUE! | G7: {=_FV(F7,"Similarity")} -> 0 | H7: {=_FV(F7,"Match")}
A8: C:\Users\73335\OneDrive - Bain\Desktop\FS-ECR-repo\fs-earnings_call_reader\src\notebooks\submission_to_fs_6thAug\FS PDFs\American International Group Inc._Earnings Call_2023-05-05_English.pdf | B8: American International Group Inc. | C8: Macro factors | D8: Tag a commentary under the Macro Factors theme if it includes any reference—explicit or implicit—to the broader macroeconomic environment or external systemic influences affecting business performance. This includes mentions of economic slowdown, recession, uncertainty, market cycles, credit losses, or challenging operating conditions. Tag if the discussion involves monetary indicators such as inflation, interest rates (domestic or foreign), discount rates, investment yields, credit spreads, or currency and foreign exchange impacts. Also include insurance and financial-specific macro drivers such as mortality experience (including seasonal or pandemic-related surges), expected credit losses (ECL), movements in insurance liabilities, or gains/losses tied to market conditions. Furthermore, tag content that refers to external shocks like pandemics (e.g. COVID-19), natural disasters (e.g. hurricanes, floods), or geopolitical disruptions. Additionally, include discussions that indirectly reflect macro context—such as tough environments, changes in investor sentiment, demand volatility, or strategic repositioning in response to macro trends—even if specific macro terms are not used. | E8: 7. Book value per common share was $\$ 58.87$ at quarter end, up $7 \%$ from year-end, principally due to higher valuations on available-for-sale securities due to lower long-term interest rates. | F8: {=_xldudf_BOARDFLARE_FMATCH(E8,'FS Consolidated Comments'!C$76:C$137,0.13)} -> #VALUE! | G8: {=_FV(F8,"Similarity")} -> 0.13 | H8: {=_FV(F8,"Match")} -> So higher interest rates have slowed the amortization on certain VFA contracts.
A9: C:\Users\73335\OneDrive - Bain\Desktop\FS-ECR-repo\fs-earnings_call_reader\src\notebooks\submission_to_fs_6thAug\FS PDFs\American International Group Inc._Earnings Call_2023-05-05_English.pdf | B9: American International Group Inc. | C9: Macro factors | D9: Tag a commentary under the Macro Factors theme if it includes any reference—explicit or implicit—to the broader macroeconomic environment or external systemic influences affecting business performance. This includes mentions of economic slowdown, recession, uncertainty, market cycles, credit losses, or challenging operating conditions. Tag if the discussion involves monetary indicators such as inflation, interest rates (domestic or foreign), discount rates, investment yields, credit spreads, or currency and foreign exchange impacts. Also include insurance and financial-specific macro drivers such as mortality experience (including seasonal or pandemic-related surges), expected credit losses (ECL), movements in insurance liabilities, or gains/losses tied to market conditions. Furthermore, tag content that refers to external shocks like pandemics (e.g. COVID-19), natural disasters (e.g. hurricanes, floods), or geopolitical disruptions. Additionally, include discussions that indirectly reflect macro context—such as tough environments, changes in investor sentiment, demand volatility, or strategic repositioning in response to macro trends—even if specific macro terms are not used. | E9: 8. Our leverage ratio declined to $32.8 \%$, down about 1 point from year-end even with the new issuance due to the change in AOCI in the quarter. | F9: {=_xldudf_BOARDFLARE_FMATCH(E9,'FS Consolidated Comments'!C$76:C$137,0.13)} -> #VALUE! | G9: {=_FV(F9,"Similarity")} -> 0 | H9: {=_FV(F9,"Match")}
A10: C:\Users\73335\OneDrive - Bain\Desktop\FS-ECR-repo\fs-earnings_call_reader\src\notebooks\submission_to_fs_6thAug\FS PDFs\American International Group Inc._Earnings Call_2023-05-05_English.pdf | B10: American International Group Inc. | C10: Macro factors | D10: Tag a commentary under the Macro Factors theme if it includes any reference—explicit or implicit—to the broader macroeconomic environment or external systemic influences affecting business performance. This includes mentions of economic slowdown, recession, uncertainty, market cycles, credit losses, or challenging operating conditions. Tag if the discussion involves monetary indicators such as inflation, interest rates (domestic or foreign), discount rates, investment yields, credit spreads, or currency and foreign exchange impacts. Also include insurance and financial-specific macro drivers such as mortality experience (including seasonal or pandemic-related surges), expected credit losses (ECL), movements in insurance liabilities, or gains/losses tied to market conditions. Furthermore, tag content that refers to external shocks like pandemics (e.g. COVID-19), natural disasters (e.g. hurricanes, floods), or geopolitical disruptions. Additionally, include discussions that indirectly reflect macro context—such as tough environments, changes in investor sentiment, demand volatility, or strategic repositioning in response to macro trends—even if specific macro terms are not used. | E10: 9. With respect to Corebridge, I took you through our current thinking on separation and timing of the secondary offerings. | F10: {=_xldudf_BOARDFLARE_FMATCH(E10,'FS Consolidated Comments'!C$76:C$137,0.13)} -> #VALUE! | G10: {=_FV(F10,"Similarity")} -> 0 | H10: {=_FV(F10,"Match")}
A11: C:\Users\73335\OneDrive - Bain\Desktop\FS-ECR-repo\fs-earnings_call_reader\src\notebooks\submission_to_fs_6thAug\FS PDFs\American International Group Inc._Earnings Call_2023-05-05_English.pdf | B11: American International Group Inc. | C11: Macro factors | D11: Tag a commentary under the Macro Factors theme if it includes any reference—explicit or implicit—to the broader macroeconomic environment or external systemic influences affecting business performance. This includes mentions of economic slowdown, recession, uncertainty, market cycles, credit losses, or challenging operating conditions. Tag if the discussion involves monetary indicators such as inflation, interest rates (domestic or foreign), discount rates, investment yields, credit spreads, or currency and foreign exchange impacts. Also include insurance and financial-specific macro drivers such as mortality experience (including seasonal or pandemic-related surges), expected credit losses (ECL), movements in insurance liabilities, or gains/losses tied to market conditions. Furthermore, tag content that refers to external shocks like pandemics (e.g. COVID-19), natural disasters (e.g. hurricanes, floods), or geopolitical disruptions. Additionally, include discussions that indirectly reflect macro context—such as tough environments, changes in investor sentiment, demand volatility, or strategic repositioning in response to macro trends—even if specific macro terms are not used. | E11: 10. We remain on track to reduce AIG common stock outstanding to be between 600 million and 650 million shares and achieve a debt-to-capital leverage at the lower end of our $20 \%$ to $25 \%$ range post deconsolidation of Corebridge. | F11: {=_xldudf_BOARDFLARE_FMATCH(E11,'FS Consolidated Comments'!C$76:C$137,0.13)} -> #VALUE! | G11: {=_FV(F11,"Similarity")} -> 0 | H11: {=_FV(F11,"Match")}
A12: C:\Users\73335\OneDrive - Bain\Desktop\FS-ECR-repo\fs-earnings_call_reader\src\notebooks\submission_to_fs_6thAug\FS PDFs\American International Group Inc._Earnings Call_2023-05-05_English.pdf | B12: American International Group Inc. | C12: Macro factors | D12: Tag a commentary under the Macro Factors theme if it includes any reference—explicit or implicit—to the broader macroeconomic environment or external systemic influences affecting business performance. This includes mentions of economic slowdown, recession, uncertainty, market cycles, credit losses, or challenging operating conditions. Tag if the discussion involves monetary indicators such as inflation, interest rates (domestic or foreign), discount rates, investment yields, credit spreads, or currency and foreign exchange impacts. Also include insurance and financial-specific macro drivers such as mortality experience (including seasonal or pandemic-related surges), expected credit losses (ECL), movements in insurance liabilities, or gains/losses tied to market conditions. Furthermore, tag content that refers to external shocks like pandemics (e.g. COVID-19), natural disasters (e.g. hurricanes, floods), or geopolitical disruptions. Additionally, include discussions that indirectly reflect macro context—such as tough environments, changes in investor sentiment, demand volatility, or strategic repositioning in response to macro trends—even if specific macro terms are not used. | E12: 11. We are confident that our continued progress on strategic initiatives and our capital management strategy will allow us to achieve our ROCE targets and deliver long-term profitable growth that benefits all of our stakeholders. | F12: {=_xldudf_BOARDFLARE_FMATCH(E12,'FS Consolidated Comments'!C$76:C$137,0.13)} -> #VALUE! | G12: {=_FV(F12,"Similarity")} -> 0 | H12: {=_FV(F12,"Match")}
A13: C:\Users\73335\OneDrive - Bain\Desktop\FS-ECR-repo\fs-earnings_call_reader\src\notebooks\submission_to_fs_6thAug\FS PDFs\American International Group Inc._Earnings Call_2023-05-05_English.pdf | B13: American International Group Inc. | C13: Macro factors | D13: Tag a commentary under the Macro Factors theme if it includes any reference—explicit or implicit—to the broader macroeconomic environment or external systemic influences affecting business performance. This includes mentions of economic slowdown, recession, uncertainty, market cycles, credit losses, or challenging operating conditions. Tag if the discussion involves monetary indicators such as inflation, interest rates (domestic or foreign), discount rates, investment yields, credit spreads, or currency and foreign exchange impacts. Also include insurance and financial-specific macro drivers such as mortality experience (including seasonal or pandemic-related surges), expected credit losses (ECL), movements in insurance liabilities, or gains/losses tied to market conditions. Furthermore, tag content that refers to external shocks like pandemics (e.g. COVID-19), natural disasters (e.g. hurricanes, floods), or geopolitical disruptions. Additionally, include discussions that indirectly reflect macro context—such as tough environments, changes in investor sentiment, demand volatility, or strategic repositioning in response to macro trends—even if specific macro terms are not used. | E13: 12. We sold and reinvested about $\$ 6$ billion in fixed maturities, resulting in a realized loss of $\$ 224$ million, but added 9 basis points of GI yield improvement for the quarter. | F13: {=_xldudf_BOARDFLARE_FMATCH(E13,'FS Consolidated Comments'!C$76:C$137,0.13)} -> #VALUE! | G13: {=_FV(F13,"Similarity")} -> 0 | H13: {=_FV(F13,"Match")}
... A81: C:\Users\73335\OneDrive - Bain\Desktop\FS-ECR-repo\fs-earnings_call_reader\src\notebooks\submission_to_fs_6thAug\FS PDFs\Manulife Financial Corporation_Earnings Call_2023-05-11_English.pdf | B81: Manulife Financial Corporation | C81: Macro factors | D81: Tag a commentary under the Macro Factors theme if it includes any reference—explicit or implicit—to the broader macroeconomic environment or external systemic influences affecting business performance. This includes mentions of economic slowdown, recession, uncertainty, market cycles, credit losses, or challenging operating conditions. Tag if the discussion involves monetary indicators such as inflation, interest rates (domestic or foreign), discount rates, investment yields, credit spreads, or currency and foreign exchange impacts. Also include insurance and financial-specific macro drivers such as mortality experience (including seasonal or pandemic-related surges), expected credit losses (ECL), movements in insurance liabilities, or gains/losses tied to market conditions. Furthermore, tag content that refers to external shocks like pandemics (e.g. COVID-19), natural disasters (e.g. hurricanes, floods), or geopolitical disruptions. Additionally, include discussions that indirectly reflect macro context—such as tough environments, changes in investor sentiment, demand volatility, or strategic repositioning in response to macro trends—even if specific macro terms are not used. | E81: 20. The market experienced losses in 2022 were primarily driven by lower-than-expected returns on public equity, net realized losses on fixed income investments and foreign exchange-related impacts, partially offset by net gains from hedge ineffectiveness and derivatives that were not in hedging relationships." | F81: {=_xldudf_BOARDFLARE_FMATCH(E81,'FS Consolidated Comments'!C$76:C$137,0.13)} -> #VALUE! | G81: {=_FV(F81,"Similarity")} -> 0 | H81: {=_FV(F81,"Match")}

Sheet FS Consolidated Comments
A1: Company | B1: Theme | C1: Commentary | D1: Page | E1: No-Match(0)/ | F1: Rationale for missing | G1: Conclusion
A2: Prudential | B2: Business/ top line growth | C2: Our Institutional Retirement Strategies business had strong first quarter sales, largely driven by our pension risk transfer business, which had its best first quarter ever with more than $2.8 billion in total new business transactions. | D2: 4 | E2: =COUNTIFS('[1]Consolidated Testing(7-10)'!$C:$C,B2,'[1]Consolidated Testing(7-10)'!$G:$G,C2,'[1]Consolidated Testing(7-10)'!$J:$J,1) -> 2 | F2: {=[2]Macro_Commentary_Classification!$C$2:$C$46} -> #VALUE!
A3: Prudential | B3: Business/ top line growth | C3: We also achieved new growth milestones in our international business, especially in Latin America, where Prudential of Brazil's sales reached double-digit year-over-year growth through our three distribution channels. | D3: 4 | E3: =COUNTIFS('[1]Consolidated Testing(7-10)'!$C:$C,B3,'[1]Consolidated Testing(7-10)'!$G:$G,C3,'[1]Consolidated Testing(7-10)'!$J:$J,1) -> 1 | F3: {=[2]Macro_Commentary_Classification!$C$2:$C$46} -> #VALUE!
A4: Prudential | B4: Business/ top line growth | C4: Our financial strength, including our AA rating is supported by $4.6 billion in highly liquid assets at the end of the first quarter as well as a high-quality, well-diversified investment portfolio and a disciplined approach to asset liability management. | D4: 5 | E4: =COUNTIFS('[1]Consolidated Testing(7-10)'!$C:$C,B4,'[1]Consolidated Testing(7-10)'!$G:$G,C4,'[1]Consolidated Testing(7-10)'!$J:$J,1) -> 0
A5: Prudential | B5: Business/ top line growth | C5: Our insurance and retirement businesses, in turn, provide a source of growth for PGIM through affiliated net flows, which totaled $2 billion in the first quarter of 2023 as well as unique access to insurance liabilities | D5: 6 | E5: =COUNTIFS('[1]Consolidated Testing(7-10)'!$C:$C,B5,'[1]Consolidated Testing(7-10)'!$G:$G,C5,'[1]Consolidated Testing(7-10)'!$J:$J,1) -> 0
A6: Prudential | B6: Macro factors | C6: These results reflect underlying business growth, including the benefits from a higher interest rate environment, offset by lower variable investment and fee income as well as elevated seasonal mortality experience | D6: 5 | E6: =COUNTIFS('[1]Consolidated Testing(7-10)'!$C:$C,B6,'[1]Consolidated Testing(7-10)'!$G:$G,C6,'[1]Consolidated Testing(7-10)'!$J:$J,1) -> 1 | F6: {=[2]Macro_Commentary_Classification!$C$2:$C$46} -> #VALUE!
A7: Prudential | B7: Business/ top line growth | C7: In Q1, we experienced third-party net outflows of $14 billion kind of driven both by Retail and Institutional. | D7: 9 | E7: =COUNTIFS('[1]Consolidated Testing(7-10)'!$C:$C,B7,'[1]Consolidated Testing(7-10)'!$G:$G,C7,'[1]Consolidated Testing(7-10)'!$J:$J,1) -> 1 | F7: {=[2]Macro_Commentary_Classification!$C$2:$C$46} -> #VALUE!
A8: Prudential | B8: Business/ top line growth | C8: And I'll just start with the institutional retirement business which ended the quarter with record account values of $253 billion. Our account values benefited from nearly $4 billion in sales, including the best first quarter ever in our pension risk transfer business | D8: 12 | E8: =COUNTIFS('[1]Consolidated Testing(7-10)'!$C:$C,B8,'[1]Consolidated Testing(7-10)'!$G:$G,C8,'[1]Consolidated Testing(7-10)'!$J:$J,1) -> 0
A9: Prudential | B9: Business/ top line growth | C9: In less than 3 years, we've delivered over $13 billion in total sales, clearly reinforcing our leadership position as a top 5 player in the indexed variable annuity space | D9: 12 | E9: =COUNTIFS('[1]Consolidated Testing(7-10)'!$C:$C,B9,'[1]Consolidated Testing(7-10)'!$G:$G,C9,'[1]Consolidated Testing(7-10)'!$J:$J,1) -> 0
A10: Prudential | B10: Business/ top line growth | C10: So let me just start by taking a step back and pointing out that at core focus, our group business is to remain price disciplined and profit focused. And that just really means pursuing smart growth. We saw a 2% growth from the year ago quarter and earned premiums and fees, and that was primarily driven by growth in disability and supplemental health. | D10: 13 | E10: =COUNTIFS('[1]Consolidated Testing(7-10)'!$C:$C,B10,'[1]Consolidated Testing(7-10)'!$G:$G,C10,'[1]Consolidated Testing(7-10)'!$J:$J,1) -> 0
A11: Prudential | B11: M&A | C11: We did programmatic M&A with the Deerpath Capital, we returned capital to shareholders, both in the form of dividends and share repurchases and we made an announcement to repay hybrid, which lowers our -- the hybrid, which lowers our leverage. | D11: 11 | E11: =COUNTIFS('[1]Consolidated Testing(7-10)'!$C:$C,B11,'[1]Consolidated Testing(7-10)'!$G:$G,C11,'[1]Consolidated Testing(7-10)'!$J:$J,1) -> 2 | F11: {=[2]Macro_Commentary_Classification!$C$2:$C$46} -> #VALUE!
A12: Manulife | B12: Business/ top line growth | C12: "Our North American insurance businesses generated strong core earnings growth compared with the prior year quarter, and we're encouraged by the momentum building in Asia." | D12: 8 | E12: =COUNTIFS('[1]Consolidated Testing(7-10)'!$C:$C,B12,'[1]Consolidated Testing(7-10)'!$G:$G,C12,'[1]Consolidated Testing(7-10)'!$J:$J,1) -> 0
A13: Manulife | B13: Business/ top line growth | C13: "Of note, Hong Kong APE sales increased 26% from the prior year quarter, reflecting a return of demand from Mainland Chinese visitors, or MCV, following the border reopening between Hong Kong and Mainland China during the quarter. And our domestic Hong Kong business remained strong with a 21% increase in sales quarter-over-quarter." | D13: 8 | E13: =COUNTIFS('[1]Consolidated Testing(7-10)'!$C:$C,B13,'[1]Consolidated Testing(7-10)'!$G:$G,C13,'[1]Consolidated Testing(7-10)'!$J:$J,1) -> 0
A14: Manulife | B14: Business/ top line growth | C14: "Core earnings in Canada increased by 6%, reflecting improved insurance experience, higher expected investment spreads and higher Manulife Bank earnings, partially offset by slower amortization of CSM." | D14: 10 | E14: =COUNTIFS('[1]Consolidated Testing(7-10)'!$C:$C,B14,'[1]Consolidated Testing(7-10)'!$G:$G,C14,'[1]Consolidated Testing(7-10)'!$J:$J,1) -> 0
A15: Manulife | B15: Business/ top line growth | C15: "In fact, our APE sales quarter-on-quarter grew 22% in Q1 versus Q4 and Asia grew 28% quarter-on-quarter. And throughout the first quarter, we saw consistent and stable increase in sales momentum, which came off the back of the restrictions being lifted." | D15: 13 | E15: =COUNTIFS('[1]Consolidated Testing(7-10)'!$C:$C,B15,'[1]Consolidated Testing(7-10)'!$G:$G,C15,'[1]Consolidated Testing(7-10)'!$J:$J,1) -> 0
A16: Manulife | B16: Business/ top line growth | C16: "And as we see that sales momentum pick up, not just in Asia but across all of our franchise, getting back to new business CSM growth at 15% and then total CSM balance growth of 8% to 10% is definitely still something we feel very confident about and certainly through our medium-term focus and targets, that's where we'd like to be, and we see ourselves." | D16: 18 | E16: =COUNTIFS('[1]Consolidated Testing(7-10)'!$C:$C,B16,'[1]Consolidated Testing(7-10)'!$G:$G,C16,'[1]Consolidated Testing(7-10)'!$J:$J,1) -> 0
A17: Manulife | B17: Business/ top line growth | C17: "The core net investment result increased 14% from the prior year quarter, driven by higher expected investment earnings, which reflects both portfolio growth and higher reinvestment yields. In addition, higher interest rates contributed to higher earnings on surplus assets." | D17: 9 | E17: =COUNTIFS('[1]Consolidated Testing(7-10)'!$C:$C,B17,'[1]Consolidated Testing(7-10)'!$G:$G,C17,'[1]Consolidated Testing(7-10)'!$J:$J,1) -> 0
A18: Manulife | B18: Business/ top line growth | C18: "Our embedded value of $63.9 billion or $34.29 per common share grew $0.94 per share in 2022, supported by robust organic growth of 11.7%." | D18: 9 | E18: =COUNTIFS('[1]Consolidated Testing(7-10)'!$C:$C,B18,'[1]Consolidated Testing(7-10)'!$G:$G,C18,'[1]Consolidated Testing(7-10)'!$J:$J,1) -> 0
A19: AIG | B19: Business/ top line growth | C19: Gross premiums written were $12 billion, an increase of 9%, with Global Commercial growing 13% and Global Personal decreasing 4%. Net premiums written were $7 billion, an increase of 10%. This growth was primarily driven by Global Commercial, which grew 11%, while Global Personal grew 6%. | D19: 5 | E19: =COUNTIFS('[1]Consolidated Testing(7-10)'!$C:$C,B19,'[1]Consolidated Testing(7-10)'!$G:$G,C19,'[1]Consolidated Testing(7-10)'!$J:$J,1) -> 0
A20: Prudential | B20: M&A | C20: Yesterday, we announced that Prudential is acquiring a majority stake in Deerpath Capital Management, a leading U.S. private credit and direct lending manager with more than $5 billion in assets under management. | D20: 4 | E20: =COUNTIFS('[1]Consolidated Testing(7-10)'!$C:$C,B20,'[1]Consolidated Testing(7-10)'!$G:$G,C20,'[1]Consolidated Testing(7-10)'!$J:$J,1) -> 2 | F20: {=[2]Macro_Commentary_Classification!$C$2:$C$46} -> #VALUE!
A21: Prudential | B21: Tech transformation | C21: First, an industry survey ranked Prudential as a top 3 carrier in e-signature adoption. A majority of annuities applications are now submitted with e-signature, which has reduced processing time by several days and improved our environmental impact. | D21: 5 | E21: =COUNTIFS('[1]Consolidated Testing(7-10)'!$C:$C,B21,'[1]Consolidated Testing(7-10)'!$G:$G,C21,'[1]Consolidated Testing(7-10)'!$J:$J,1) -> 1 | F21: {=[2]Macro_Commentary_Classification!$C$2:$C$46} -> #VALUE!
A22: AIG | B22: Business/ top line growth | C22: In North America Commercial, we saw a very strong growth of 15% in net premiums written due to Validus Re, which had over 40% growth year-over-year due to the exceptional results we achieved with our January 1 treaty placements, which I discussed in detail on our last call | D22: 5 | E22: =COUNTIFS('[1]Consolidated Testing(7-10)'!$C:$C,B22,'[1]Consolidated Testing(7-10)'!$G:$G,C22,'[1]Consolidated Testing(7-10)'!$J:$J,1) -> 0
A23: AIG | B23: Business/ top line growth | C23: Strong retention, new business and rate have been the key drivers of Lexington's financial performance. Lexington has now seen double-digit rate increases for 16 consecutive quarters, and cumulative compounded rate increases totaled over 100% since the first quarter of 2018. | D23: 5 | E23: =COUNTIFS('[1]Consolidated Testing(7-10)'!$C:$C,B23,'[1]Consolidated Testing(7-10)'!$G:$G,C23,'[1]Consolidated Testing(7-10)'!$J:$J,1) -> 0
A24: Prudential | B24: Operational/ cost efficiency | C24: And then finally, we remain focused on expense discipline. and continuous improvement in operating efficiency with an eye towards protecting the bottom line. | D24: 12 | E24: =COUNTIFS('[1]Consolidated Testing(7-10)'!$C:$C,B24,'[1]Consolidated Testing(7-10)'!$G:$G,C24,'[1]Consolidated Testing(7-10)'!$J:$J,1) -> 1 | F24: {=[2]Macro_Commentary_Classification!$C$2:$C$46} -> #VALUE!
A25: Prudential | B25: Product Expansion | C25: . In the U.S., our individual retirement strategies business continued to expand its suite of next-generation protection solutions. We expanded our FlexGuard distribution and introduced new product enhancements to meet the evolving needs of our customers | D25: 4 | E25: =COUNTIFS('[1]Consolidated Testing(7-10)'!$C:$C,B25,'[1]Consolidated Testing(7-10)'!$G:$G,C25,'[1]Consolidated Testing(7-10)'!$J:$J,1) -> 2 | F25: {=[2]Macro_Commentary_Classification!$C$2:$C$46} -> #VALUE!
A26: AIG | B26: Business/ top line growth | C26: Additionally, over the last few years, the average size of a Lexington Property primary policy went from $100 million in limits deployed to $5 million. | D26: 5 | E26: =COUNTIFS('[1]Consolidated Testing(7-10)'!$C:$C,B26,'[1]Consolidated Testing(7-10)'!$G:$G,C26,'[1]Consolidated Testing(7-10)'!$J:$J,1) -> 0
A27: AIG | B27: Business/ top line growth | C27: Net premiums written were very strong and balanced in Validus Re, and we continue to meaningfully improve the quality of the portfolio. Rate improvements were particularly strong in U.S. Property, International Property, Marine and Energy, Casualty and Specialty Lines. | D27: 5 | E27: =COUNTIFS('[1]Consolidated Testing(7-10)'!$C:$C,B27,'[1]Consolidated Testing(7-10)'!$G:$G,C27,'[1]Consolidated Testing(7-10)'!$J:$J,1) -> 0
A28: Prudential | B28: Product Expansion | C28: We do continue to believe that this business is core to Prudential's purpose and we like the growth potential with our overall brand as well as our product breadth and certainly our distribution strength. | D28: 10 | E28: =COUNTIFS('[1]Consolidated Testing(7-10)'!$C:$C,B28,'[1]Consolidated Testing(7-10)'!$G:$G,C28,'[1]Consolidated Testing(7-10)'!$J:$J,1) -> 1 | F28: {=[2]Macro_Commentary_Classification!$C$2:$C$46} -> #VALUE!
A29: Prudential | B29: Product Expansion | C29: our work on innovating our product designs continues as we drive to ensure that we meet the needs for retirement, wealth transfer and unmet health and care needs. | D29: 14 | E29: =COUNTIFS('[1]Consolidated Testing(7-10)'!$C:$C,B29,'[1]Consolidated Testing(7-10)'!$G:$G,C29,'[1]Consolidated Testing(7-10)'!$J:$J,1) -> 1 | F29: {=[2]Macro_Commentary_Classification!$C$2:$C$46} -> #VALUE!
A30: Prudential | B30: Regulatory or accounting update | C30: Yes, the NAIC is in the process of addressing what is uneconomic issues with the IMR. They -- as you mentioned, they've released a proposal, and that's out for comment until June 9. | D30: 8 | E30: =COUNTIFS('[1]Consolidated Testing(7-10)'!$C:$C,B30,'[1]Consolidated Testing(7-10)'!$G:$G,C30,'[1]Consolidated Testing(7-10)'!$J:$J,1) -> 1 | F30: {=[2]Macro_Commentary_Classification!$C$2:$C$46} -> #VALUE!
A31: Prudential | B31: Regulatory or accounting update | C31: So obviously, as you state, LDTI is expected to result in a meaningful decline in earnings this year for the Life business as AOI recognition will be deferred | D31: 10 | E31: =COUNTIFS('[1]Consolidated Testing(7-10)'!$C:$C,B31,'[1]Consolidated Testing(7-10)'!$G:$G,C31,'[1]Consolidated Testing(7-10)'!$J:$J,1) -> 1 | F31: {=[2]Macro_Commentary_Classification!$C$2:$C$46} -> #VALUE!
A32: AIG | B32: Business/ top line growth | C32: Turning to International Commercial. Net premiums written grew 6%, primarily due to Property, which was up over 40%; Global Specialty, which was up over 15%; and Casualty, which was up over 15%. Global Commercial had very strong renewal retention of 88% in its in-force portfolio, International was up 200 basis points to 88%, and North America was up 100 basis points to 87% | D32: 6 | E32: =COUNTIFS('[1]Consolidated Testing(7-10)'!$C:$C,B32,'[1]Consolidated Testing(7-10)'!$G:$G,C32,'[1]Consolidated Testing(7-10)'!$J:$J,1) -> 0
A33: Manulife | B33: Macro factors | C33: "Our result reflects the quality of our fixed income portfolio amid a challenging global macroeconomic environment in 2022." | D33: 6 | E33: =COUNTIFS('[1]Consolidated Testing(7-10)'!$C:$C,B33,'[1]Consolidated Testing(7-10)'!$G:$G,C33,'[1]Consolidated Testing(7-10)'!$J:$J,1) -> 1 | F33: {=[2]Macro_Commentary_Classification!$C$2:$C$46} -> #VALUE! | H33: =[2]Macro_Commentary_Classification!$C10 -> Not Relevant
A34: AIG | B34: Business/ top line growth | C34: International Commercial new business was over $590 million, led by Specialty, which increased its new business by over 50%, driven by Energy and Marine. North America Commercial, excluding Validus Re, achieved new business of over $480 million, driven by Lexington, which saw excellent new business growth of over 50%. | D34: 6 | E34: =COUNTIFS('[1]Consolidated Testing(7-10)'!$C:$C,B34,'[1]Consolidated Testing(7-10)'!$G:$G,C34,'[1]Consolidated Testing(7-10)'!$J:$J,1) -> 0 | H34: =[2]Macro_Commentary_Classification!$C11 -> Relevant
A35: AIG | B35: Business/ top line growth | C35: The combination of improved pricing in our admitted business and more business migrating to the non-admitting market has a very positive impact on PCG's accident and policy or loss ratios. | D35: 6 | E35: =COUNTIFS('[1]Consolidated Testing(7-10)'!$C:$C,B35,'[1]Consolidated Testing(7-10)'!$G:$G,C35,'[1]Consolidated Testing(7-10)'!$J:$J,1) -> 0
A36: Prudential | B36: Tech transformation | C36: We continue to enhance the ways in which customers engage with our products and solutions to drive more digital experiences and better customer outcomes. | D36: 5 | E36: =COUNTIFS('[1]Consolidated Testing(7-10)'!$C:$C,B36,'[1]Consolidated Testing(7-10)'!$G:$G,C36,'[1]Consolidated Testing(7-10)'!$J:$J,1) -> 2 | F36: {=[2]Macro_Commentary_Classification!$C$2:$C$46} -> #VALUE!
A37: Manulife | B37: Macro factors | C37: "We expect the magnitude of market experience impact to reduce going forward." | D37: 6 | E37: =COUNTIFS('[1]Consolidated Testing(7-10)'!$C:$C,B37,'[1]Consolidated Testing(7-10)'!$G:$G,C37,'[1]Consolidated Testing(7-10)'!$J:$J,1) -> 2 | F37: {=[2]Macro_Commentary_Classification!$C$2:$C$46} -> #VALUE!
A38: AIG | B38: Business/ top line growth | C38: Turning to International Personal. Net premiums written were largely flat in the first quarter, Travel and Warranty grew while Personal Property declined, all driven by a further refinement of our cat reinsurance cost allocation methodology, making year-overyear comparisons difficult | D38: 7 | E38: =COUNTIFS('[1]Consolidated Testing(7-10)'!$C:$C,B38,'[1]Consolidated Testing(7-10)'!$G:$G,C38,'[1]Consolidated Testing(7-10)'!$J:$J,1) -> 0
A39: AIG | B39: Business/ top line growth | C39: As I mentioned earlier, premiums and deposits grew significantly in the first quarter, driven by strong new individual retirement business, which, despite increasing surrenders related to interest rates, contributed to growth in the General Account. | D39: 7 | E39: =COUNTIFS('[1]Consolidated Testing(7-10)'!$C:$C,B39,'[1]Consolidated Testing(7-10)'!$G:$G,C39,'[1]Consolidated Testing(7-10)'!$J:$J,1) -> 0
A40: Manulife | B40: Macro factors | C40: "We reported strong operating results against the challenging backdrop of market volatility, persistent inflation, continued recession concerns and stress in the banking sector." | D40: 8 | E40: =COUNTIFS('[1]Consolidated Testing(7-10)'!$C:$C,B40,'[1]Consolidated Testing(7-10)'!$G:$G,C40,'[1]Consolidated Testing(7-10)'!$J:$J,1) -> 1 | F40: {=[2]Macro_Commentary_Classification!$C$2:$C$46} -> #VALUE!
...
